Workbook

Sheet Hoja1
A1: Temario | B1: Tema | C1: Descripcion_Tema | D1: Test | E1: Descripcion_test | F1: Pregunta | G1: Enunciado | H1: a | I1: b | J1: c | K1: d | L1: solucion
A2: Jurídico | B2: 1 | C2: Constitución | D2: 1 | E2: Test Ayuntamiento 1 | F2: 1 | G2: A tenor del contenido del articulo 1.1. de la Constitucion española de 1978, ¿en que tipo de Estado se constituyo el Estado español? | H2: Social, liberal y de derecho. | I2: Democratico, de derecho y social | J2: Social, democratico y capitalista | L2: b
A3: Jurídico | B3: 1 | C3: Constitución | D3: 1 | E3: Test Ayuntamiento 1 | F3: 2 | G3: El Estatuto de Autonomia es: | H3: Una norma estatal, al ser parte de su ordenamiento juridico. | I3: Norma institucional basica de cada CCAA | J3: Ley Organica cualificada en su elaboracion, tramitacion y reforma | L3: b
A4: Jurídico | B4: 1 | C4: Constitución | D4: 2 | E4: Test Constitución 16 2023 | F4: 1 | G4: ¿En qué parte de la Constitución se señalan los valores del ordenamiento jurídico? | H4: En el Preámbulo | I4: En el Título Preliminar | J4: En El Título I | K4: Ninguna respuesta es correcta | L4: b
A5: Jurídico | B5: 1 | C5: Constitución | D5: 2 | E5: Test Constitución 16 2023 | F5: 2 | G5: Los valores superiores del ordenamiento jurídico son: | H5: Libertad, justicia, seguridad y pluralismo político | I5: Seguridad, justicia, igualdad y pluralismo político | J5: Libertad, justicia, pluralismo político e igualdad | K5: Ninguna respuesta es correcta | L5: c
A6: Jurídico | B6: 1 | C6: Constitución | D6: 2 | E6: Test Constitución 16 2023 | F6: 3 | G6: Son el fundamento del orden político y de la paz social: | H6: El libre desarrollo de la personalidad | I6: Los derechos inviolables que le son inherentes | J6: El respeto a la Ley y a los derechos de los demás | K6: Todas las respuestas son correctas | L6: d
A7: Jurídico | B7: 1 | C7: Constitución | D7: 2 | E7: Test Constitución 16 2023 | F7: 4 | G7: Según la Constitución, debe garantizarse siempre la audiencia de los ciudadanos en el: | H7: Procedimiento de elaboración de las disposiciones administrativas que le afecten. | I7: Procedimiento a través del cual se produzcan los actos administrativos. | J7: Total actuar de la administración. | K7: Procedimiento de elaboración de las disposiciones administrativas que le afecten y en el procedimiento a través del cual se produzcan los actos administrativos. | L7: a
A8: Jurídico | B8: 1 | C8: Constitución | D8: 2 | E8: Test Constitución 16 2023 | F8: 5 | G8: Los órganos de la Administración del Estado, son creados, regidos y coordinados: | H8: De acuerdo con los principios marcados por el Ministerio para las Administraciones Públicas. | I8: De acuerdo con los exigencias del Gobierno. | J8: De acuerdo con la Ley. | K8: De acuerdo con las exigencias de los ciudadanos. | L8: c
A9: Jurídico | B9: 1 | C9: Constitución | D9: 2 | E9: Test Constitución 16 2023 | F9: 6 | G9: El Consejo de Estado debe ser regulado: | H9: Mediante ley ordinaria. | I9: Puede serio mediante ley de bases. | J9: Puede ser objeto su regulación de delegación legislativa. | K9: Mediante ley orgánica. | L9: d
A10: Jurídico | B10: 1 | C10: Constitución | D10: 2 | E10: Test Constitución 16 2023 | F10: 7 | G10: ¿Quién representa al Gobierno estatal en una Comunidad Autónoma? | H10: El Delegado del Gobierno | I10: El Presidente de la Comunidad Autónoma | J10: El Consejo de Gobierno | K10: El Subdelegado del Gobierno | L10: a
A11: Jurídico | B11: 1 | C11: Constitución | D11: 2 | E11: Test Constitución 16 2023 | F11: 8 | G11: No podrán acceder al autogobierno: | H11: Las provincias con entidad regional histórica. | I11: Las provincias limítrofes con características económicas comunes. | J11: Los territorios insulares. | K11: Las provincias limítrofes con características sociales comunes. | L11: d
A12: Jurídico | B12: 1 | C12: Constitución | D12: 2 | E12: Test Constitución 16 2023 | F12: 9 | G12: El poder ejecutivo de una Comunidad Autónoma se ejerce por el: | H12: Consejo de Gobierno | I12: Consejo colegiado | J12: Consejo | K12: Consejo ejecutivo. | L12: a
A13: Jurídico | B13: 1 | C13: Constitución | D13: 2 | E13: Test Constitución 16 2023 | F13: 10 | G13: ¿A qué materia está dedicado el Título IV? | H13: A las Cortes Generales. | I13: Al Gobierno. | J13: Al Gobierno y a las Cortes Generales. | K13: Al Gobierno y a la Administración. | L13: d
A14: Jurídico | B14: 1 | C14: Constitución | D14: 2 | E14: Test Constitución 16 2023 | F14: 11 | G14: ¿En qué se fundamenta la Constitución, según el art. 2 de la misma? | H14: En el pueblo español que la refrendó. | I14: En la indisoluble unidad de la nación española. | J14: En el poder soberano de las Cortes Generales. | K14: En el estado democrático. | L14: b
A15: Jurídico | B15: 1 | C15: Constitución | D15: 2 | E15: Test Constitución 16 2023 | F15: 12 | G15: ¿Qué artículo del Título I recoge el principio de igualdad jurídica de los españoles ante la ley? | H15: El artículo 12. | I15: El artículo 11. | J15: El artículo 14. | K15: El artículo 16 | L15: c
... A79: Jurídico | B79: 1 | C79: Constitución | D79: 4 | E79: TEST CUCALON 2 | F79: 29 | G79: Se reconoce autonomía en la Constitución española a: | H79: A las comunidades autónomas y a las regiones | I79: A las regiones y a las nacionalidades | J79: A las regiones | K79: A las nacionalidades y comunidades autónomas | L79: b
A80: Jurídico | B80: 2 | C80: Ley Org. 5/2007 Estatuto de Autonomia | D80: 5 | E80: Test competencias 1 | F80: 5 | G80: En el ámbito de las competencias ejecutivas y en orden a la aplicación de la legislación estatal, la Comunidad Autónoma de Aragón podrá dictar reglamentos para la regulación de su propia competencia funcional y la organización de los servicios necesarios para ello, y en general podrá ejercer todas aquellas funciones y actividades que el ordenamiento jurídico atribuye a la Administración Pública. Corresponde a la Comunidad Autónoma la competencia ejecutiva en las siguientes materias: | H80: Gestión de la asistencia sanitaria de la Seguridad Social. Productos farmacéuticos. | I80: Museos, archivos, bibliotecas y otras colecciones de naturaleza análoga de titularidad estatal cuya gestión no se reserve la Administración General del Estado. | J80: A y B son correctas | L80: c
A81: Jurídico | B81: 2 | C81: Ley Org. 5/2007 Estatuto de Autonomia | D81: 5 | E81: Test competencias 1 | F81: 6 | G81: La materia referida a “Denominaciones de origen y otras menciones de calidad”, es una competencia de la Comunidad Autónoma de Aragón: | H81: Compartida. | I81: Exclusiva. | J81: Ejecutiva. | L81: b
A82: Jurídico | B82: 2 | C82: Ley Org. 5/2007 Estatuto de Autonomia | D82: 5 | E82: Test competencias 1 | F82: 7 | G82: La materia referida a “Ordenación del territorio, conforme a los principios de equilibrio territorial, demográfico, socioeconómico y ambiental”, es una competencia de la Comunidad Autónoma de Aragón: | H82: Compartida. | I82: Exclusiva. | J82: Ejecutiva. | L82: b
A83: Jurídico | B83: 2 | C83: Ley Org. 5/2007 Estatuto de Autonomia | D83: 5 | E83: Test competencias 1 | F83: 8 | G83: La materia referida a “Régimen jurídico, procedimiento, contratación y responsabilidad de la Administración Pública de la Comunidad Autónoma ”, es una competencia de la Comunidad Autónoma de Aragón: | H83: Compartida. | I83: Exclusiva. | J83: Ejecutiva. | L83: a
A84: Jurídico | B84: 2 | C84: Ley Org. 5/2007 Estatuto de Autonomia | D84: 5 | E84: Test competencias 1 | F84: 9 | G84: La materia referida a “Aeropuertos, helipuertos y otras infraestructuras de transporte aéreo, con calificación de interés general, cuya gestión directa no se reserve la Administración General del Estado”, es una competencia de la Comunidad Autónoma de Aragón: | H84: Compartida. | I84: Exclusiva. | J84: Ejecutiva. | L84: c
A85: Jurídico | B85: 2 | C85: Ley Org. 5/2007 Estatuto de Autonomia | D85: 5 | E85: Test competencias 1 | F85: 10 | G85: En el ámbito de las competencias exclusivas, la Comunidad Autónoma de Aragón ejercerá: | H85: El desarrollo legislativo, el reglamentario, la función ejecutiva y el establecimiento de políticas propias. | I85: La potestad legislativa, la potestad reglamentaria, la función ejecutiva y el establecimiento de políticas propias. | J85: Ninguna es correcta. | L85: b
A86: Jurídico | B86: 2 | C86: Ley Org. 5/2007 Estatuto de Autonomia | D86: 5 | E86: Test competencias 1 | F86: 11 | G86: La materia referida a “Políticas de igualdad social, que comprenden el establecimiento de medidas de discriminación positiva, prevención y protección social ante todo tipo de violencia, y, especialmente, la de género”, es una competencia de la Comunidad Autónoma de Aragón: | H86: Compartida. | I86: Exclusiva. | J86: Ejecutiva. | L86: b
A87: Jurídico | B87: 2 | C87: Ley Org. 5/2007 Estatuto de Autonomia | D87: 5 | E87: Test competencias 1 | F87: 12 | G87: La materia referida a “ Ordenación del crédito, banca, seguros, mutualidades de previsión social, entidades gestoras de planes y fondos de pensiones y otras mutualidades no integradas en el sistema de Seguridad Social ”, es una competencia de la Comunidad Autónoma de Aragón: | H87: Compartida. | I87: Exclusiva. | J87: Ejecutiva. | L87: a
A88: Jurídico | B88: 2 | C88: Ley Org. 5/2007 Estatuto de Autonomia | D88: 5 | E88: Test competencias 1 | F88: 13 | G88: La materia referida a “ Mercados de valores y centros de contratación situados en el territorio de Aragón, que, en todo caso, incluye su regulación, establecimiento y solvencia, de acuerdo con la legislación mercantil ”, es una competencia de la Comunidad Autónoma de Aragón: | H88: Compartida. | I88: Exclusiva. | J88: Ejecutiva. | L88: a
A89: Jurídico | B89: 2 | C89: Ley Org. 5/2007 Estatuto de Autonomia | D89: 5 | E89: Test competencias 1 | F89: 14 | G89: La regulación de la protección y defensa de los consumidores y usuarios; el fomento de las asociaciones; la formación y educación para el consumo responsable, es competencia: | H89: Exclusiva de la CCAA de Aragón. | I89: Exclusiva del Estado. | J89: Compartida. | L89: a
A90: Jurídico | B90: 2 | C90: Ley Org. 5/2007 Estatuto de Autonomia | D90: 5 | E90: Test competencias 1 | F90: 15 | G90: La materia referida a “Colaboración con el Estado en la gestión del catastro”, es una competencia de la Comunidad Autónoma de Aragón: | H90: Compartida. | I90: Exclusiva. | J90: Ejecutiva | L90: c
A91: Jurídico | B91: 2 | C91: Ley Org. 5/2007 Estatuto de Autonomia | D91: 5 | E91: Test competencias 1 | F91: 16 | G91: Cuando la Comunidad Autónoma de Aragón ejerce el desarrollo legislativo y la ejecución de la legislación básica que establezca el Estado, nos estamos refiriendo a competencias: | H91: Compartidas. | I91: Ejecutivas. | J91: Exclusivas. | L91: a
... A99: Jurídico | B99: 2 | C99: Ley Org. 5/2007 Estatuto de Autonomia | D99: 6 | E99: Test competencias 2 | F99: 4 | G99: La materia referida a “Colegios profesionales y ejercicio de profesiones tituladas”, es una competencia de la Comunidad Autónoma de Aragón: | H99: Exclusiva | I99: Compartida. | J99: Ejecutiva. | L99: a
A100: Jurídico | B100: 2 | C100: Ley Org. 5/2007 Estatuto de Autonomia | D100: 6 | E100: Test competencias 2 | F100: 5 | G100: El vigente Estatuto de Autonomía de Aragón aprobado por Ley orgánica 5/2007 de 20 de Abril, nos habla de tres tipos de competencias en su artículo 70: | H100: Competencias exclusivas, competencias compartidas y competencias generales. | I100: Competencias exclusivas. Competencias compartidas y competencias ejecutivas. | J100: Competencias exclusivas, competencias compartidas y competencias generales y competencias ejecutivas. | K100: Competencias exclusivas, competencias ejecutivas y competencias generales. | L100: b
A101: Jurídico | B101: 2 | C101: Ley Org. 5/2007 Estatuto de Autonomia | D101: 6 | E101: Test competencias 2 | F101: 6 | G101: Según dispone el artículo 74 del Estatuto de Autonomía de Aragón, la competencia en medios de comunicación social y servicios de contenido audiovisual es: | H101: Una competencia exclusiva. | I101: Una competencia compartida. | J101: Una competencia concurrente. | K101: Una competencia concurrente y además ejecutiva. | L101: b
A102: Jurídico | B102: 2 | C102: Ley Org. 5/2007 Estatuto de Autonomia | D102: 6 | E102: Test competencias 2 | F102: 7 | G102: Señala la falsa. Es competencia exclusiva de la Comunidad Autónoma de Aragón: | H102: El control metrológico y el contraste de metales. | I102: La organización territorial propia de la Comunidad Autónoma. | J102: Vivienda, que, en todo caso, incluye la planificación, la ordenación, la gestión, el fomento, la inspección y el control de la vivienda de acuerdo con las necesidades sociales de equilibrio territorial y de sostenibilidad. | L102: a
A103: Jurídico | B103: 2 | C103: Ley Org. 5/2007 Estatuto de Autonomia | D103: 6 | E103: Test competencias 2 | F103: 8 | G103: Sanidad y salud pública, en especial, la organización, el funcionamiento, la evaluación, la inspección y el control de centros, servicios y establecimientos sanitarios, es para la Comunidad Autónoma de Aragón, conforme al Estatuto de Autonomía de Aragón una competencia: | H103: Exclusiva. | I103: Compartida. | J103: Ejecutiva. | L103: a
A104: Jurídico | B104: 2 | C104: Ley Org. 5/2007 Estatuto de Autonomia | D104: 6 | E104: Test competencias 2 | F104: 9 | G104: En enseñanza en toda su extensión, niveles y grados, modalidades y especialidades, tiene la Comunidad Autónoma de Aragón; | H104: Competencia exclusiva. | I104: Competencia compartida. | J104: Competencia ejecutiva. | L104: b
A105: Jurídico | B105: 2 | C105: Ley Org. 5/2007 Estatuto de Autonomia | D105: 6 | E105: Test competencias 2 | F105: 10 | G105: ¿Qué titulo de los siguientes, del Estatuto de Autonomía de Aragón, no está subdividido en cuatro capítulos?: | H105: Economía y Hacienda. | I105: Cooperación Institucional y Acción Exterior. | J105: Competencias de la Comunidad Autónoma. | L105: c
A106: Jurídico | B106: 2 | C106: Ley Org. 5/2007 Estatuto de Autonomia | D106: 6 | E106: Test competencias 2 | F106: 11 | G106: El control de la actividad de los órganos de las Comunidades Autónomas se ejercerá por (señala la NO CORRECTA): | H106: Por el Tribunal de Cuentas, el económico y presupuestario. | I106: Por el Gobierno, previo dictamen del Consejo de Estado, el del ejercicio defunciones delegadas a que se refiere el apartado 2 del artículo 150. | J106: Por el Consejo General del Poder Judicial, el de la administración y sus normas reglamentarias. | L106: c
A107: Jurídico | B107: 2 | C107: Ley Org. 5/2007 Estatuto de Autonomia | D107: 6 | E107: Test competencias 2 | F107: 12 | G107: Conforme a lo establecido en la Constitución Española, la apreciación de la necesidad de armonizar las normas dictadas por las Comunidades Autónomas mediante una ley de las Cortes Generales, corresponde: | H107: Al Tribunal Constitucional. | I107: Al Congreso de los Diputados, por mayoría absoluta. | J107: Al Congreso y al Senado, por mayoría absoluta de cada Cámara. | L107: c
A108: Jurídico | B108: 2 | C108: Ley Org. 5/2007 Estatuto de Autonomia | D108: 6 | E108: Test competencias 2 | F108: 13 | G108: La organización territorial propia de la Comunidad Autónoma de Aragón, es competencia: | H108: Del Estado, conforme a lo establecido en la Constitución Española. | I108: Exclusiva de la CCAA de Aragón, conforme se establece en su Estatuto. | J108: Compartida, la CCAA de Aragón ejercerá el desarrollo legislativo y la ejecución de la legislación básica que establezca el Estado. | L108: b
A109: Jurídico | B109: 2 | C109: Ley Org. 5/2007 Estatuto de Autonomia | D109: 6 | E109: Test competencias 2 | F109: 14 | G109: En el Estatuto de Autonomía de Aragón se establece: | H109: Corresponde a la CCAA de Aragón la competencia compartida en enseñanza en toda su extensión. | I109: La CCAA de Aragón podrá regular, crear y mantener su propia televisión, radio y prensa y, en general, cualquier medio de comunicación social para el cumplimiento de sus fines, respetando la autonomía local. | J109: A y B son correctas. | L109: c
A110: Jurídico | B110: 2 | C110: Ley Org. 5/2007 Estatuto de Autonomia | D110: 6 | E110: Test competencias 2 | F110: 15 | G110: Cuando la CCAA de Aragón ejerce el desarrollo legislativo y la ejecución de la legislación básica que establezca el Estado, nos estamos refiriendo a competencias: | H110: Compartidas. | I110: Ejecutivas. | J110: Exclusivas. | L110: a
...

Sheet Conteo
A2: Etiquetas de fila | B2: Cuenta de Pregunta
A3: Específico | B3: 1623
A4: Carpinteria | B4: 252
A5: Albañileria | B5: 210
A6: Ofimatica | B6: 167
A7: Aparatos de audio, video e imagen | B7: 165
A8: Fontaneria | B8: 159
A9: Persianas | B9: 118
A10: Prevencion | B10: 75
A11: Incendios | B11: 73
A12: Electricidad | B12: 59
A13: Cerrajeria | B13: 53
A14: Alarmas | B14: 52
... A35: Prevencion | B35: 3
A36: (en blanco)
A37: (en blanco)
A38: Total general | B38: 2355

Sheet Temas
A1: Temario | B1: Tema | C1: Descripcion_Tema
A2: Específico | B2: 0 | C2: Supuestos Practicos
A3: Jurídico | B3: 1 | C3: Constitución
A4: Jurídico | B4: =B3+1 -> 2 | C4: Ley Org. 5/2007 Estatuto de Autonomia
A5: Jurídico | B5: =B4+1 -> 3 | C5: Ley 39/2015 Procedimiento Adm. Común.
A6: Jurídico | B6: =B5+1 -> 4 | C6: R.D.L. 2/2004 Ley Haciendas Locales
A7: Jurídico | B7: =B6+1 -> 5 | C7: Ley 7/1985 Reguladora de las Bases del Regimen Local
A8: Jurídico | B8: =B7+1 -> 6 | C8: R.D.L. 5/2015 T.R.E.B.E.P
A9: Jurídico | B9: =B8+1 -> 7 | C9: Ley 10/2017 Regimen especial Municipio Zaragoza
A10: Jurídico | B10: =B9+1 -> 8 | C10: Ley 3/2007 Igualdad
A11: Específico | B11: =B10+1 -> 9 | C11: Electricidad
A12: Específico | B12: =B11+1 -> 10 | C12: Albañileria
A13: Específico | B13: =B12+1 -> 11 | C13: Fontaneria
A14: Específico | B14: =B13+1 -> 12 | C14: Carpinteria
A15: Específico | B15: =B14+1 -> 13 | C15: Cerrajeria
... A37: Específico | B37: =B36+1 -> 35 | C37: Productos fitosanitarios

Sheet Estrategia
A1: Preguntas totales | B1: 50 | D1: Estrategia, si me suena alguna respuesta, valorar. Si descarto 1 respuesta, jugarmela
A2: Penalizacion | B2: 0.33
A4: Aciertos | B4: 45 | C4: 40 | D4: 35 | E4: 30 | F4: 25
A5: Fallos | B5: 0 | C5: 0 | D5: 0 | E5: 0 | F5: 0
A6: NOTA | B6: =(B4-(B5*$B$2))/$B$1*10 -> 9 | C6: =(C4-(C5*$B$2))/$B$1*10 -> 8 | D6: =(D4-(D5*$B$2))/$B$1*10 -> 7 | E6: =(E4-(E5*$B$2))/$B$1*10 -> 6 | F6: =(F4-(F5*$B$2))/$B$1*10 -> 5
A8: 5 fallos | B8: =(5*B2)/B1*10 -> 0.33
A9: 10 fallos | B9: =(10*B2)/B1*10 -> 0.66
A10: 15 fallos | B10: =(15*B2)/B1*10 -> 0.99
